# Plan de correction du traitement par lots d'images

## Notes

- La mise en œuvre actuelle de `upscale_batch` dans `image_enhancement.py` présente un bug dans l'agrégation des résultats. Lorsqu'une image est trouvée dans le cache (session ou fichier), son résultat n'est pas correctement inséré dans la liste finale, ce qui conduit à une valeur `None` et à l'échec de l'assertion du test.
- Le problème n'est pas la génération de la clé de cache, mais la reconstruction de la liste de résultats.
- Le script de test a révélé une erreur HTTP 422 (`Unprocessable Entity`) lors de l'appel à l'API `extra-batch-images`. Cela était dû à des valeurs non valides pour `upscaling_resize_w` et `upscaling_resize_h`. Une correction a été appliquée.
- Le script de test échouait lors du traitement d'un mélange d'images mises en cache et non mises en cache. L'erreur initiale était due à un appel à une méthode `get_cached_path` inexistante. La méthode a été ajoutée à `ImageCache` et le script de test a été corrigé pour utiliser `is_cached` pour la validation.
- Le test a ensuite échoué avec une `NameError` pour `Any` dans `image_cache.py`, qui a été corrigée en ajoutant l'importation manquante.
- L'analyse approfondie des fichiers (`image_enhancement.py`, `image_cache.py`, `test_batch_processing.py`) confirme que la logique de cache (génération de clé, vérification, ajout) est saine. Le problème principal est isolé dans la méthode `upscale_batch` : elle n'agrège pas correctement les résultats lorsque des images sont récupérées du cache, ce qui entraîne une liste de résultats désordonnée et l'échec du script de test.
- La méthode `add_to_cache` dans `image_cache.py` a été nettoyée pour supprimer le code redondant.
- La revue de `image_enhancement.py`, `image_cache.py`, et `test_batch_processing.py` confirme que la stratégie de refactoring de `upscale_batch` est correcte. La logique de cache est saine, le problème réside bien dans l'agrégation des résultats (mis en cache et nouveaux) dans le bon ordre.
- Le dernier test a échoué dans le scénario 2 (mélange d'images en cache et nouvelles). La première image, qui aurait dû être trouvée dans le cache, a renvoyé `None`. Cela confirme que le bug se trouve dans la logique de `upscale_batch` qui gère les éléments mis en cache et assemble la liste de résultats finale. La recherche dans le cache ou la génération de la clé de cache semble échouer dans ce contexte.
- Une modification de `get_cache_key` pour normaliser et trier les paramètres a été implémentée pour assurer une génération de clé de cache cohérente. Bien que cela ait résolu les divergences de clés, le test échoue toujours, confirmant que le problème principal est l'agrégation des résultats.
- L'analyse des logs après la correction de la clé de cache montre que les images sont correctement identifiées dans le cache, mais que la liste de résultats finale est mal construite par `upscale_batch`, ce qui entraîne l'échec du test.
- L'utilisateur a suggéré de remplacer le cache basé sur des fichiers JSON par une base de données (par exemple, SQLite) pour améliorer la robustesse. C'est une amélioration potentielle à considérer après la correction du bug actuel.
- Des logs détaillés ont été ajoutés à `get_cache_key` et `is_cached` pour tracer la génération et la vérification des clés. L'analyse de ces logs est la prochaine étape pour identifier la cause exacte de l'échec de la mise en cache.
- L'analyse détaillée de `image_enhancement.py`, `image_cache.py` et `test_batch_processing.py` confirme que l'échec du test dans le scénario 2 est très probablement dû à une incohérence dans les paramètres de cache. La méthode `upscale_batch` et la section de validation du script de test construisent probablement le dictionnaire `cache_params` différemment, ce qui entraîne l'échec de `is_cached`.
- La revue de `test_batch_processing.py` montre qu'il reconstruit manuellement le dictionnaire `cache_params`. C'est une approche fragile qui peut facilement conduire à des divergences par rapport à la logique de `_get_cache_params` dans `image_enhancement.py`. L'échec de `is_cached` dans le scénario 2 suggère fortement une différence subtile (ordre des clés, valeurs par défaut, types) entre les paramètres utilisés lors de l'ajout au cache et ceux utilisés lors de la vérification.
- Le projet a été nettoyé : les anciennes notes de version ont été archivées, et le script de test et son log ont été déplacés dans le dossier `tests` pour une meilleure organisation.
- Le dernier test a échoué avec une `NameError: name 'json' is not defined` dans `test_batch_processing.py`, qui a été corrigée.
- Le test a ensuite échoué avec une `AssertionError` dans le scénario 2. La logique de validation du cache dans le script de test était incorrecte : elle vérifiait l'état du cache *après* le traitement du lot, moment où les nouvelles images avaient déjà été ajoutées au cache.
- La logique de validation du test a été corrigée pour vérifier correctement que les images du lot précédent sont récupérées du cache et que les nouvelles images sont traitées et leurs sorties créées.
- Le script de test `test_batch_processing.py` passe maintenant avec succès, validant que la logique de cache et le traitement de lots mixtes (en cache et nouveaux) fonctionnent comme prévu.
- La méthode `is_cached` dans `image_cache.py` a été modifiée pour retourner optionnellement le chemin du fichier mis en cache, en plus du statut booléen. Sa signature de retour est maintenant `Union[bool, Tuple[bool, Optional[Path]]]`. 
- La méthode `get_cached_path` dans `image_cache.py`, devenue redondante après la mise à jour de `is_cached`, a été supprimée avec succès. Tous les appels pertinents (`_process_single_image`, `upscale_batch`, `process_image`) avaient déjà été mis à jour.
- L'examen de `test_image_cache.py` révèle que les tests actuels ne couvrent pas la nouvelle fonctionnalité de `is_cached` (le retour du chemin de cache). Des tests supplémentaires ont été ajoutés.
- Les nouveaux tests pour `test_image_cache.py` ont échoué avec des erreurs `TypeError` et `NameError`. Cela était dû à l'absence du paramètre `return_cached_path` dans la signature de la méthode `is_cached`.
- La signature de `is_cached` a été corrigée, mais l'implémentation doit maintenant être ajustée pour gérer correctement la nouvelle logique et les valeurs de retour, et pour corriger l'erreur `NameError` dans le bloc `except`.
- La méthode `is_cached` a été corrigée pour retourner systématiquement un tuple `(False, None)` lorsque `return_cached_path` est `True` et que la vérification du cache échoue (fichier non trouvé, hash incorrect, etc.). Cela a résolu les erreurs `TypeError` et tous les tests dans `test_image_cache.py` passent maintenant.
- L'exécution de la suite de tests complète a révélé des erreurs `TypeError` dans `processor.py`. La cause est que les mocks de `is_cached` dans `test_processor.py` n'ont pas été mis à jour pour retourner un tuple `(bool, Optional[Path])` lorsque `return_cached_path=True`, mais retournent toujours un simple booléen.
- Les mocks dans `test_processor.py` ont été corrigés pour retourner un tuple, et les tests de ce fichier passent maintenant.
- La suite de tests complète échouait initialement avec 7 erreurs. Les `NameError` (imports manquants de `random` et `time`) et la `TypeError` dans la gestion des codes de statut HTTP ont été corrigées. Il reste 4 tests en échec à investiguer, principalement des `AssertionError`.
- Le passage à `hashlib.sha256` a corrigé l'erreur de longueur de hachage (`assert 16 == 64`). Cependant, un nouvel échec est apparu dans `test_end_to_end_processing`: `assert metadata_file.exists()`.
- L'analyse de `cli.py` confirme que la logique de traitement est correcte : les fichiers sont d'abord renommés avec un hachage, puis la liste des nouveaux chemins est passée à la fonction de traitement des métadonnées. La cause de l'échec n'est donc pas l'ordre des opérations.
- L'analyse des tests montre que les logs de débogage pour `metadata.py` ne sont pas activés dans `test_end_to_end_processing` car l'argument `--verbose` n'est pas passé au script via `sys.argv`. C'est la raison pour laquelle l'échec de la sauvegarde est silencieux. Le test `test_process_option_metadata_only`, qui passe, inclut bien cet argument.
- L'analyse des tests montre que les logs de débogage pour `metadata.py` ne sont pas activés dans `test_end_to_end_processing` car l'argument `--verbose` n'est pas passé au script via `sys.argv`. C'est la raison pour laquelle l'échec de la sauvegarde est silencieux. Le test `test_process_option_metadata_only`, qui passe, inclut bien cet argument.
- La tentative de correction du bug des métadonnées (en passant les `processed_files` à `process_metadata`) a introduit une `UnboundLocalError`. La variable `processed_files` n'est pas initialisée si l'étape de renommage est sautée, ce qui fait échouer les tests qui ne concernent que les métadonnées. La correction de cette erreur a révélé un problème plus profond.
- Les échecs des tests `test_end_to_end_processing` et `test_process_option_metadata_only` sont dus à une logique défectueuse dans `cli.py` pour déterminer les fichiers à envoyer au traitement des métadonnées. Pour `metadata-only`, il cherche les fichiers dans le dossier de sortie (qui est vide) au lieu du dossier d'entrée.
- Un avertissement `TypeError: get_default_cache() got an unexpected keyword argument 'cache_dir'` a été observé lors de l'exécution des tests. Cela indique un problème dans la configuration du cache à partir de la CLI.
- La correction de la logique de sélection des fichiers dans `cli.py` a résolu le problème pour `test_process_option_metadata_only`, qui passe maintenant.
- Cependant, `test_end_to_end_processing` (mode `all`) échoue toujours car les fichiers de métadonnées ne sont pas créés pour les images renommées (hachées).
- La cause probable est un problème dans la manière dont `process_metadata` gère les chemins de fichiers qui se trouvent déjà dans le répertoire de sortie.
- L'ajout de `--verbose` au test `test_end_to_end_processing` a permis d'obtenir des logs détaillés. L'analyse de ces logs montre que l'étape de traitement des métadonnées n'est pas du tout visible, ce qui suggère qu'elle n'est pas appelée pour les fichiers renommés.
- Une erreur `AttributeError: 'str' object has no attribute 'name'` est survenue car les objets `Path` étaient convertis en chaînes de caractères trop tôt dans `cli.py`. La correction consiste à conserver les objets `Path` dans la liste `processed_files`.
- Le problème principal de l'échec du test `test_end_to_end_processing` est une incohérence de nommage. Le test s'attend à ce qu'un fichier image nommé `[hash].jpg` ait un fichier de métadonnées nommé `[hash]_metadata.json`. Cependant, le code recalculait un hachage du contenu du fichier de sortie pour nommer le fichier de métadonnées, et ce nouveau hachage était différent du hachage du nom de fichier. La solution est d'utiliser le nom (stem) du fichier image comme base pour le nom du fichier de métadonnées.
- La tentative de correction du nommage des fichiers de métadonnées a échoué car la modification a été appliquée dans `extract_and_save_metadata`, mais pas dans `save_metadata` qui est la fonction qui écrit réellement le fichier. `save_metadata` continue d'utiliser le hachage de contenu (`content_hash`) pour nommer le fichier, ce qui est la cause de l'échec du test.
- La correction de `save_metadata` pour utiliser le nom de l'image (stem) au lieu du hachage du contenu a résolu l'échec du test `test_end_to_end_processing`. Le test passe maintenant, confirmant que les métadonnées sont correctement générées pour les fichiers renommés.
- L'exécution de la suite de tests complète a révélé 7 échecs, indiquant des régressions et des tests fragiles suite au changement de stratégie de nommage des métadonnées.
- Les échecs dans `test_metadata.py` sont dus au fait que les tests s'attendaient à un nommage basé sur le hachage de contenu (pour la déduplication), alors que le code utilise désormais le nom du fichier source. Les tests doivent être alignés sur le nouveau comportement.
- D'autres échecs indiquent une régression dans le traitement par lots/cache, un test CLI fragile qui ne tient pas compte de l'ordre des fichiers, et une gestion incorrecte des erreurs dans les tests d'amélioration d'image.
- Les tests dans `test_metadata.py` ont été corrigés avec succès. Les assertions ont été mises à jour pour correspondre à la nouvelle stratégie de nommage basée sur le nom du fichier source (stem), et pour tenir compte du fait que l'ordre de traitement des fichiers n'est pas garanti.
- La méthode `_process_single_image` a été refactorisée pour une gestion plus robuste des chemins (en utilisant des chemins absolus) et une journalisation améliorée. La méthode `_get_output_path` sera également mise à jour pour assurer la cohérence.
- L'analyse de `upscale_image` montre que la méthode retourne un `str` au lieu d'un objet `Path`, ce qui contredit sa signature de type `-> Tuple[Path, bool]` et cause des échecs de test.

## Liste des tâches

- [x] Adapter le code à la nouvelle signature de `is_cached`.
  - [x] Mettre à jour `_process_single_image` dans `image_enhancement.py`.
  - [x] Mettre à jour `upscale_batch` dans `image_enhancement.py` pour utiliser le chemin de retour de `is_cached`.
  - [x] Mettre à jour `process_image` dans `processor.py`.
  - [x] Mettre à jour les scripts de test (`test_batch_processing.py`, `test_image_cache.py`, `test_processor.py`) pour refléter les changements.
    - [x] Ajouter des tests pour la nouvelle signature de `is_cached` dans `test_image_cache.py`.
    - [x] Corriger l'implémentation de `is_cached` pour gérer le paramètre `return_cached_path` et les erreurs de test.
    - [x] Exécuter les tests de `test_image_cache.py` et s'assurer qu'ils passent.
    - [x] Corriger les mocks dans `test_processor.py` pour retourner un tuple.
- [x] Corriger l'erreur de payload HTTP 422 dans `upscale_batch`.
  - [x] Analyser la construction du payload pour l'endpoint `extra-batch-images`.
  - [x] S'assurer que `upscaling_resize_w` et `upscaling_resize_h` sont calculés et inclus correctement.
- [x] Supprimer la méthode `get_cached_path` inutilisée dans `image_cache.py`.
- [ ] Envisager de remplacer le cache basé sur JSON par une solution de base de données (par exemple, SQLite) pour une meilleure robustesse.
- [x] Nettoyer la structure du projet.
  - [x] Déplacer `test_batch_processing.py` dans le dossier `tests`.
  - [x] Déplacer `test_batch_processing.log` dans le dossier `tests/logs`.
  - [x] Valider et pousser les changements sur Git.
  - [x] Nettoyer la racine du projet des fichiers et dossiers superflus.
- [x] Exécuter l'ensemble de la suite de tests pour s'assurer qu'il n'y a pas de régressions.
  - [x] Corriger les `NameError` (imports manquants de `random` et `time`).
  - [x] Corriger la `TypeError` dans `test_stable_diffusion_api.py`.
  - [ ] Corriger les `AssertionError` restantes dans les tests.
    - [x] `test_end_to_end_processing`: `assert 16 == 64` -> Problème de hachage/nom de fichier.
    - [x] `test_end_to_end_processing`: La sauvegarde des métadonnées échoue en mode `all`.
      - [x] Corriger la logique pour le mode `metadata-only` (le test `test_process_option_metadata_only` passe).
      - [x] Ajouter `--verbose` à `test_end_to_end_processing` pour obtenir des logs de débogage.
      - [x] Analyser les logs et corriger la cause de l'échec de la création des métadonnées dans `cli.py`.
      - [x] Corriger `save_metadata` dans `metadata.py` pour utiliser le nom de l'image (stem) pour nommer le fichier de métadonnées, et non le hachage du contenu.
      - [x] S'assurer que tous les tests d'intégration passent.
- [ ] Refactoriser `image_enhancement.py` pour une meilleure gestion des chemins et des erreurs.
  - [x] Améliorer `_process_single_image` avec des chemins absolus, une meilleure journalisation et une gestion des erreurs plus fine.
  - [ ] Mettre à jour `_get_output_path` pour qu'elle retourne systématiquement des chemins absolus.
- [ ] Corriger les 7 régressions et tests échoués de la suite de tests complète.
  - [x] Corriger les échecs dans `test_metadata.py` en alignant les tests sur la nouvelle stratégie de nommage par nom de fichier.
    - [x] `test_save_metadata`: Mettre à jour l'assertion pour vérifier le nom basé sur le `stem` de l'image.
    - [x] `test_extract_and_save_metadata`: Mettre à jour l'assertion pour vérifier le nom basé sur le `stem`.
    - [x] `test_process_metadata_function`: Mettre à jour l'assertion pour s'attendre à un fichier de métadonnées par image d'entrée (pas de déduplication).
  - [ ] Corriger l'échec de `test_batch_processing.py::test_batch_processing` (régression du cache).
  - [ ] Corriger l'échec de `test_cli_extra.py::test_main_processing_error` en rendant le test insensible à l'ordre des fichiers.
  - [ ] Corriger les échecs dans `test_image_enhancement.py`.
    - [ ] `test_call_api_error_handling`: Mettre à jour l'assertion du message d'erreur.
    - [ ] `test_upscale_batch_with_error_handling`: Corriger la logique de gestion des erreurs de lot.
    - [ ] Corriger `upscale_image` pour qu'elle retourne un objet `Path` comme l'indique sa signature de type.
- [ ] Supprimer les logs de débogage une fois tous les bugs corrigés.
- [ ] Exécuter une dernière fois la suite de tests complète pour valider toutes les corrections.
{{ ... }}

## Objectif actuel

Corriger le type de retour de `upscale_image`.